[2024-01-21T08:59:54.085+0000] {taskinstance.py:1159} INFO - Dependencies all met for dep_context=non-requeueable deps ti=<TaskInstance: data_ingestion.load_data manual__2024-01-21T08:59:49.756931+00:00 [queued]>
[2024-01-21T08:59:54.090+0000] {taskinstance.py:1159} INFO - Dependencies all met for dep_context=requeueable deps ti=<TaskInstance: data_ingestion.load_data manual__2024-01-21T08:59:49.756931+00:00 [queued]>
[2024-01-21T08:59:54.090+0000] {taskinstance.py:1361} INFO - Starting attempt 1 of 1
[2024-01-21T08:59:54.094+0000] {taskinstance.py:1382} INFO - Executing <Task(_PythonDecoratedOperator): load_data> on 2024-01-21 08:59:49.756931+00:00
[2024-01-21T08:59:54.098+0000] {standard_task_runner.py:57} INFO - Started process 31532 to run task
[2024-01-21T08:59:54.100+0000] {standard_task_runner.py:84} INFO - Running: ['***', 'tasks', 'run', 'data_ingestion', 'load_data', 'manual__2024-01-21T08:59:49.756931+00:00', '--job-id', '284', '--raw', '--subdir', 'DAGS_FOLDER/fetch-api-data.py', '--cfg-path', '/tmp/tmp2yl5yj8h']
[2024-01-21T08:59:54.102+0000] {standard_task_runner.py:85} INFO - Job 284: Subtask load_data
[2024-01-21T08:59:54.121+0000] {task_command.py:416} INFO - Running <TaskInstance: data_ingestion.load_data manual__2024-01-21T08:59:49.756931+00:00 [running]> on host 1cee5fdf7640
[2024-01-21T08:59:54.223+0000] {taskinstance.py:1662} INFO - Exporting env vars: AIRFLOW_CTX_DAG_OWNER='***' AIRFLOW_CTX_DAG_ID='data_ingestion' AIRFLOW_CTX_TASK_ID='load_data' AIRFLOW_CTX_EXECUTION_DATE='2024-01-21T08:59:49.756931+00:00' AIRFLOW_CTX_TRY_NUMBER='1' AIRFLOW_CTX_DAG_RUN_ID='manual__2024-01-21T08:59:49.756931+00:00'
[2024-01-21T08:59:54.227+0000] {base.py:73} INFO - Using connection ID 'postgres_conn' for task execution.
[2024-01-21T08:59:54.227+0000] {taskinstance.py:1937} ERROR - Task failed with exception
Traceback (most recent call last):
  File "/home/airflow/.local/lib/python3.8/site-packages/airflow/decorators/base.py", line 221, in execute
    return_value = super().execute(context)
  File "/home/airflow/.local/lib/python3.8/site-packages/airflow/operators/python.py", line 192, in execute
    return_value = self.execute_callable()
  File "/home/airflow/.local/lib/python3.8/site-packages/airflow/operators/python.py", line 209, in execute_callable
    return self.python_callable(*self.op_args, **self.op_kwargs)
  File "/opt/airflow/dags/fetch-api-data.py", line 59, in load_data
    connection = pg_hook.get_conn()
AttributeError: 'Connection' object has no attribute 'get_conn'
[2024-01-21T08:59:54.231+0000] {taskinstance.py:1400} INFO - Marking task as FAILED. dag_id=data_ingestion, task_id=load_data, execution_date=20240121T085949, start_date=20240121T085954, end_date=20240121T085954
[2024-01-21T08:59:54.236+0000] {standard_task_runner.py:104} ERROR - Failed to execute job 284 for task load_data ('Connection' object has no attribute 'get_conn'; 31532)
[2024-01-21T08:59:54.273+0000] {local_task_job_runner.py:228} INFO - Task exited with return code 1
[2024-01-21T08:59:54.281+0000] {taskinstance.py:2778} INFO - 0 downstream tasks scheduled from follow-on schedule check
