[2024-01-14T09:00:03.666+0000] {taskinstance.py:1159} INFO - Dependencies all met for dep_context=non-requeueable deps ti=<TaskInstance: data_ingestion.load_data scheduled__2024-01-13T09:00:00+00:00 [queued]>
[2024-01-14T09:00:03.669+0000] {taskinstance.py:1159} INFO - Dependencies all met for dep_context=requeueable deps ti=<TaskInstance: data_ingestion.load_data scheduled__2024-01-13T09:00:00+00:00 [queued]>
[2024-01-14T09:00:03.669+0000] {taskinstance.py:1361} INFO - Starting attempt 1 of 1
[2024-01-14T09:00:03.674+0000] {taskinstance.py:1382} INFO - Executing <Task(_PythonDecoratedOperator): load_data> on 2024-01-13 09:00:00+00:00
[2024-01-14T09:00:03.677+0000] {standard_task_runner.py:57} INFO - Started process 27856 to run task
[2024-01-14T09:00:03.679+0000] {standard_task_runner.py:84} INFO - Running: ['***', 'tasks', 'run', 'data_ingestion', 'load_data', 'scheduled__2024-01-13T09:00:00+00:00', '--job-id', '226', '--raw', '--subdir', 'DAGS_FOLDER/fetch-api-data.py', '--cfg-path', '/tmp/tmpivrtrbz9']
[2024-01-14T09:00:03.680+0000] {standard_task_runner.py:85} INFO - Job 226: Subtask load_data
[2024-01-14T09:00:03.698+0000] {task_command.py:416} INFO - Running <TaskInstance: data_ingestion.load_data scheduled__2024-01-13T09:00:00+00:00 [running]> on host f28e5db0fcbc
[2024-01-14T09:00:03.733+0000] {taskinstance.py:1662} INFO - Exporting env vars: AIRFLOW_CTX_DAG_OWNER='***' AIRFLOW_CTX_DAG_ID='data_ingestion' AIRFLOW_CTX_TASK_ID='load_data' AIRFLOW_CTX_EXECUTION_DATE='2024-01-13T09:00:00+00:00' AIRFLOW_CTX_TRY_NUMBER='1' AIRFLOW_CTX_DAG_RUN_ID='scheduled__2024-01-13T09:00:00+00:00'
[2024-01-14T09:00:03.733+0000] {taskinstance.py:1937} ERROR - Task failed with exception
Traceback (most recent call last):
  File "/home/airflow/.local/lib/python3.8/site-packages/airflow/decorators/base.py", line 221, in execute
    return_value = super().execute(context)
  File "/home/airflow/.local/lib/python3.8/site-packages/airflow/operators/python.py", line 192, in execute
    return_value = self.execute_callable()
  File "/home/airflow/.local/lib/python3.8/site-packages/airflow/operators/python.py", line 209, in execute_callable
    return self.python_callable(*self.op_args, **self.op_kwargs)
  File "/opt/airflow/dags/fetch-api-data.py", line 52, in load_data
    for column in holiday_df.columns:
AttributeError: 'NoneType' object has no attribute 'columns'
[2024-01-14T09:00:03.738+0000] {taskinstance.py:1400} INFO - Marking task as FAILED. dag_id=data_ingestion, task_id=load_data, execution_date=20240113T090000, start_date=20240114T090003, end_date=20240114T090003
[2024-01-14T09:00:03.744+0000] {standard_task_runner.py:104} ERROR - Failed to execute job 226 for task load_data ('NoneType' object has no attribute 'columns'; 27856)
[2024-01-14T09:00:03.772+0000] {local_task_job_runner.py:228} INFO - Task exited with return code 1
[2024-01-14T09:00:03.779+0000] {taskinstance.py:2778} INFO - 0 downstream tasks scheduled from follow-on schedule check
