[2024-01-21T09:00:04.066+0000] {taskinstance.py:1159} INFO - Dependencies all met for dep_context=non-requeueable deps ti=<TaskInstance: data_ingestion.load_data scheduled__2024-01-20T09:00:00+00:00 [queued]>
[2024-01-21T09:00:04.070+0000] {taskinstance.py:1159} INFO - Dependencies all met for dep_context=requeueable deps ti=<TaskInstance: data_ingestion.load_data scheduled__2024-01-20T09:00:00+00:00 [queued]>
[2024-01-21T09:00:04.071+0000] {taskinstance.py:1361} INFO - Starting attempt 1 of 1
[2024-01-21T09:00:04.077+0000] {taskinstance.py:1382} INFO - Executing <Task(_PythonDecoratedOperator): load_data> on 2024-01-20 09:00:00+00:00
[2024-01-21T09:00:04.081+0000] {standard_task_runner.py:57} INFO - Started process 31551 to run task
[2024-01-21T09:00:04.084+0000] {standard_task_runner.py:84} INFO - Running: ['***', 'tasks', 'run', 'data_ingestion', 'load_data', 'scheduled__2024-01-20T09:00:00+00:00', '--job-id', '287', '--raw', '--subdir', 'DAGS_FOLDER/fetch-api-data.py', '--cfg-path', '/tmp/tmpsi2k5ikv']
[2024-01-21T09:00:04.086+0000] {standard_task_runner.py:85} INFO - Job 287: Subtask load_data
[2024-01-21T09:00:04.108+0000] {task_command.py:416} INFO - Running <TaskInstance: data_ingestion.load_data scheduled__2024-01-20T09:00:00+00:00 [running]> on host 1cee5fdf7640
[2024-01-21T09:00:04.194+0000] {taskinstance.py:1662} INFO - Exporting env vars: AIRFLOW_CTX_DAG_OWNER='***' AIRFLOW_CTX_DAG_ID='data_ingestion' AIRFLOW_CTX_TASK_ID='load_data' AIRFLOW_CTX_EXECUTION_DATE='2024-01-20T09:00:00+00:00' AIRFLOW_CTX_TRY_NUMBER='1' AIRFLOW_CTX_DAG_RUN_ID='scheduled__2024-01-20T09:00:00+00:00'
[2024-01-21T09:00:04.198+0000] {base.py:73} INFO - Using connection ID 'postgres_conn' for task execution.
[2024-01-21T09:00:04.198+0000] {taskinstance.py:1937} ERROR - Task failed with exception
Traceback (most recent call last):
  File "/home/airflow/.local/lib/python3.8/site-packages/airflow/decorators/base.py", line 221, in execute
    return_value = super().execute(context)
  File "/home/airflow/.local/lib/python3.8/site-packages/airflow/operators/python.py", line 192, in execute
    return_value = self.execute_callable()
  File "/home/airflow/.local/lib/python3.8/site-packages/airflow/operators/python.py", line 209, in execute_callable
    return self.python_callable(*self.op_args, **self.op_kwargs)
  File "/opt/airflow/dags/fetch-api-data.py", line 59, in load_data
    connection = pg_hook.get_conn()
AttributeError: 'Connection' object has no attribute 'get_conn'
[2024-01-21T09:00:04.203+0000] {taskinstance.py:1400} INFO - Marking task as FAILED. dag_id=data_ingestion, task_id=load_data, execution_date=20240120T090000, start_date=20240121T090004, end_date=20240121T090004
[2024-01-21T09:00:04.207+0000] {standard_task_runner.py:104} ERROR - Failed to execute job 287 for task load_data ('Connection' object has no attribute 'get_conn'; 31551)
[2024-01-21T09:00:04.217+0000] {local_task_job_runner.py:228} INFO - Task exited with return code 1
[2024-01-21T09:00:04.227+0000] {taskinstance.py:2778} INFO - 0 downstream tasks scheduled from follow-on schedule check
