[2024-02-22T10:40:39.704+0000] {taskinstance.py:1159} INFO - Dependencies all met for dep_context=non-requeueable deps ti=<TaskInstance: data_ingestion.load_data manual__2024-02-22T10:40:36.131218+00:00 [queued]>
[2024-02-22T10:40:39.708+0000] {taskinstance.py:1159} INFO - Dependencies all met for dep_context=requeueable deps ti=<TaskInstance: data_ingestion.load_data manual__2024-02-22T10:40:36.131218+00:00 [queued]>
[2024-02-22T10:40:39.708+0000] {taskinstance.py:1361} INFO - Starting attempt 1 of 1
[2024-02-22T10:40:39.713+0000] {taskinstance.py:1382} INFO - Executing <Task(_PythonDecoratedOperator): load_data> on 2024-02-22 10:40:36.131218+00:00
[2024-02-22T10:40:39.715+0000] {standard_task_runner.py:57} INFO - Started process 1468 to run task
[2024-02-22T10:40:39.717+0000] {standard_task_runner.py:84} INFO - Running: ['***', 'tasks', 'run', 'data_ingestion', 'load_data', 'manual__2024-02-22T10:40:36.131218+00:00', '--job-id', '367', '--raw', '--subdir', 'DAGS_FOLDER/fetch-api-data.py', '--cfg-path', '/tmp/tmpqpt1__gz']
[2024-02-22T10:40:39.719+0000] {standard_task_runner.py:85} INFO - Job 367: Subtask load_data
[2024-02-22T10:40:39.737+0000] {task_command.py:416} INFO - Running <TaskInstance: data_ingestion.load_data manual__2024-02-22T10:40:36.131218+00:00 [running]> on host 8ffe65393bc1
[2024-02-22T10:40:39.810+0000] {taskinstance.py:1662} INFO - Exporting env vars: AIRFLOW_CTX_DAG_OWNER='***' AIRFLOW_CTX_DAG_ID='data_ingestion' AIRFLOW_CTX_TASK_ID='load_data' AIRFLOW_CTX_EXECUTION_DATE='2024-02-22T10:40:36.131218+00:00' AIRFLOW_CTX_TRY_NUMBER='1' AIRFLOW_CTX_DAG_RUN_ID='manual__2024-02-22T10:40:36.131218+00:00'
[2024-02-22T10:40:39.814+0000] {base.py:73} INFO - Using connection ID '***_conn' for task execution.
[2024-02-22T10:40:39.814+0000] {logging_mixin.py:154} INFO - Error while connecting to PostgreSQL 'Connection' object has no attribute 'cursor'
[2024-02-22T10:40:39.814+0000] {taskinstance.py:1937} ERROR - Task failed with exception
Traceback (most recent call last):
  File "/home/airflow/.local/lib/python3.8/site-packages/airflow/decorators/base.py", line 221, in execute
    return_value = super().execute(context)
  File "/home/airflow/.local/lib/python3.8/site-packages/airflow/operators/python.py", line 192, in execute
    return_value = self.execute_callable()
  File "/home/airflow/.local/lib/python3.8/site-packages/airflow/operators/python.py", line 209, in execute_callable
    return self.python_callable(*self.op_args, **self.op_kwargs)
  File "/opt/airflow/dags/fetch-api-data.py", line 78, in load_data
    cursor.close()
UnboundLocalError: local variable 'cursor' referenced before assignment
[2024-02-22T10:40:39.818+0000] {taskinstance.py:1400} INFO - Marking task as FAILED. dag_id=data_ingestion, task_id=load_data, execution_date=20240222T104036, start_date=20240222T104039, end_date=20240222T104039
[2024-02-22T10:40:39.822+0000] {standard_task_runner.py:104} ERROR - Failed to execute job 367 for task load_data (local variable 'cursor' referenced before assignment; 1468)
[2024-02-22T10:40:39.854+0000] {local_task_job_runner.py:228} INFO - Task exited with return code 1
[2024-02-22T10:40:39.861+0000] {taskinstance.py:2778} INFO - 0 downstream tasks scheduled from follow-on schedule check
