[2024-02-22T15:05:10.319+0000] {taskinstance.py:1159} INFO - Dependencies all met for dep_context=non-requeueable deps ti=<TaskInstance: data_ingestion.load_data manual__2024-02-22T15:05:06.168950+00:00 [queued]>
[2024-02-22T15:05:10.323+0000] {taskinstance.py:1159} INFO - Dependencies all met for dep_context=requeueable deps ti=<TaskInstance: data_ingestion.load_data manual__2024-02-22T15:05:06.168950+00:00 [queued]>
[2024-02-22T15:05:10.324+0000] {taskinstance.py:1361} INFO - Starting attempt 1 of 1
[2024-02-22T15:05:10.328+0000] {taskinstance.py:1382} INFO - Executing <Task(_PythonDecoratedOperator): load_data> on 2024-02-22 15:05:06.168950+00:00
[2024-02-22T15:05:10.331+0000] {standard_task_runner.py:57} INFO - Started process 8628 to run task
[2024-02-22T15:05:10.333+0000] {standard_task_runner.py:84} INFO - Running: ['***', 'tasks', 'run', 'data_ingestion', 'load_data', 'manual__2024-02-22T15:05:06.168950+00:00', '--job-id', '394', '--raw', '--subdir', 'DAGS_FOLDER/fetch-api-data.py', '--cfg-path', '/tmp/tmpdtqcg2q3']
[2024-02-22T15:05:10.334+0000] {standard_task_runner.py:85} INFO - Job 394: Subtask load_data
[2024-02-22T15:05:10.353+0000] {task_command.py:416} INFO - Running <TaskInstance: data_ingestion.load_data manual__2024-02-22T15:05:06.168950+00:00 [running]> on host 8ffe65393bc1
[2024-02-22T15:05:10.427+0000] {taskinstance.py:1662} INFO - Exporting env vars: AIRFLOW_CTX_DAG_OWNER='***' AIRFLOW_CTX_DAG_ID='data_ingestion' AIRFLOW_CTX_TASK_ID='load_data' AIRFLOW_CTX_EXECUTION_DATE='2024-02-22T15:05:06.168950+00:00' AIRFLOW_CTX_TRY_NUMBER='1' AIRFLOW_CTX_DAG_RUN_ID='manual__2024-02-22T15:05:06.168950+00:00'
[2024-02-22T15:05:10.432+0000] {base.py:73} INFO - Using connection ID '***_conn' for task execution.
[2024-02-22T15:05:10.432+0000] {logging_mixin.py:154} INFO - Error while connecting to PostgreSQL 'str' object has no attribute 'cursor'
[2024-02-22T15:05:10.432+0000] {taskinstance.py:1937} ERROR - Task failed with exception
Traceback (most recent call last):
  File "/home/airflow/.local/lib/python3.8/site-packages/airflow/decorators/base.py", line 221, in execute
    return_value = super().execute(context)
  File "/home/airflow/.local/lib/python3.8/site-packages/airflow/operators/python.py", line 192, in execute
    return_value = self.execute_callable()
  File "/home/airflow/.local/lib/python3.8/site-packages/airflow/operators/python.py", line 209, in execute_callable
    return self.python_callable(*self.op_args, **self.op_kwargs)
  File "/opt/airflow/dags/fetch-api-data.py", line 88, in load_data
    cursor.close()
AttributeError: 'NoneType' object has no attribute 'close'
[2024-02-22T15:05:10.436+0000] {taskinstance.py:1400} INFO - Marking task as FAILED. dag_id=data_ingestion, task_id=load_data, execution_date=20240222T150506, start_date=20240222T150510, end_date=20240222T150510
[2024-02-22T15:05:10.440+0000] {standard_task_runner.py:104} ERROR - Failed to execute job 394 for task load_data ('NoneType' object has no attribute 'close'; 8628)
[2024-02-22T15:05:10.466+0000] {local_task_job_runner.py:228} INFO - Task exited with return code 1
[2024-02-22T15:05:10.474+0000] {taskinstance.py:2778} INFO - 0 downstream tasks scheduled from follow-on schedule check
