[2024-01-20T14:48:56.242+0000] {taskinstance.py:1159} INFO - Dependencies all met for dep_context=non-requeueable deps ti=<TaskInstance: data_ingestion.load_data manual__2024-01-20T14:48:53.497005+00:00 [queued]>
[2024-01-20T14:48:56.245+0000] {taskinstance.py:1159} INFO - Dependencies all met for dep_context=requeueable deps ti=<TaskInstance: data_ingestion.load_data manual__2024-01-20T14:48:53.497005+00:00 [queued]>
[2024-01-20T14:48:56.245+0000] {taskinstance.py:1361} INFO - Starting attempt 1 of 1
[2024-01-20T14:48:56.250+0000] {taskinstance.py:1382} INFO - Executing <Task(_PythonDecoratedOperator): load_data> on 2024-01-20 14:48:53.497005+00:00
[2024-01-20T14:48:56.253+0000] {standard_task_runner.py:57} INFO - Started process 1922 to run task
[2024-01-20T14:48:56.254+0000] {standard_task_runner.py:84} INFO - Running: ['***', 'tasks', 'run', 'data_ingestion', 'load_data', 'manual__2024-01-20T14:48:53.497005+00:00', '--job-id', '251', '--raw', '--subdir', 'DAGS_FOLDER/fetch-api-data.py', '--cfg-path', '/tmp/tmpgdx5nlno']
[2024-01-20T14:48:56.256+0000] {standard_task_runner.py:85} INFO - Job 251: Subtask load_data
[2024-01-20T14:48:56.275+0000] {task_command.py:416} INFO - Running <TaskInstance: data_ingestion.load_data manual__2024-01-20T14:48:53.497005+00:00 [running]> on host 1cee5fdf7640
[2024-01-20T14:48:56.352+0000] {taskinstance.py:1662} INFO - Exporting env vars: AIRFLOW_CTX_DAG_OWNER='***' AIRFLOW_CTX_DAG_ID='data_ingestion' AIRFLOW_CTX_TASK_ID='load_data' AIRFLOW_CTX_EXECUTION_DATE='2024-01-20T14:48:53.497005+00:00' AIRFLOW_CTX_TRY_NUMBER='1' AIRFLOW_CTX_DAG_RUN_ID='manual__2024-01-20T14:48:53.497005+00:00'
[2024-01-20T14:48:56.356+0000] {base.py:73} INFO - Using connection ID 'postgres_conn' for task execution.
[2024-01-20T14:48:56.359+0000] {logging_mixin.py:154} INFO - An error occurred: (psycopg2.OperationalError) connection to server at "host.docker.internal" (192.168.65.254), port 5432 failed: Connection refused
	Is the server running on that host and accepting TCP/IP connections?

(Background on this error at: https://sqlalche.me/e/14/e3q8)
[2024-01-20T14:48:56.360+0000] {python.py:194} INFO - Done. Returned value was: None
[2024-01-20T14:48:56.363+0000] {taskinstance.py:1400} INFO - Marking task as SUCCESS. dag_id=data_ingestion, task_id=load_data, execution_date=20240120T144853, start_date=20240120T144856, end_date=20240120T144856
[2024-01-20T14:48:56.390+0000] {local_task_job_runner.py:228} INFO - Task exited with return code 0
[2024-01-20T14:48:56.398+0000] {taskinstance.py:2778} INFO - 0 downstream tasks scheduled from follow-on schedule check
