[2024-01-21T13:41:05.247+0000] {taskinstance.py:1159} INFO - Dependencies all met for dep_context=non-requeueable deps ti=<TaskInstance: data_ingestion.load_data manual__2024-01-21T13:41:01.477159+00:00 [queued]>
[2024-01-21T13:41:05.251+0000] {taskinstance.py:1159} INFO - Dependencies all met for dep_context=requeueable deps ti=<TaskInstance: data_ingestion.load_data manual__2024-01-21T13:41:01.477159+00:00 [queued]>
[2024-01-21T13:41:05.251+0000] {taskinstance.py:1361} INFO - Starting attempt 1 of 1
[2024-01-21T13:41:05.256+0000] {taskinstance.py:1382} INFO - Executing <Task(_PythonDecoratedOperator): load_data> on 2024-01-21 13:41:01.477159+00:00
[2024-01-21T13:41:05.259+0000] {standard_task_runner.py:57} INFO - Started process 39208 to run task
[2024-01-21T13:41:05.261+0000] {standard_task_runner.py:84} INFO - Running: ['***', 'tasks', 'run', 'data_ingestion', 'load_data', 'manual__2024-01-21T13:41:01.477159+00:00', '--job-id', '308', '--raw', '--subdir', 'DAGS_FOLDER/fetch-api-data.py', '--cfg-path', '/tmp/tmpnimozbsd']
[2024-01-21T13:41:05.262+0000] {standard_task_runner.py:85} INFO - Job 308: Subtask load_data
[2024-01-21T13:41:05.281+0000] {task_command.py:416} INFO - Running <TaskInstance: data_ingestion.load_data manual__2024-01-21T13:41:01.477159+00:00 [running]> on host 1cee5fdf7640
[2024-01-21T13:41:05.406+0000] {taskinstance.py:1662} INFO - Exporting env vars: AIRFLOW_CTX_DAG_OWNER='***' AIRFLOW_CTX_DAG_ID='data_ingestion' AIRFLOW_CTX_TASK_ID='load_data' AIRFLOW_CTX_EXECUTION_DATE='2024-01-21T13:41:01.477159+00:00' AIRFLOW_CTX_TRY_NUMBER='1' AIRFLOW_CTX_DAG_RUN_ID='manual__2024-01-21T13:41:01.477159+00:00'
[2024-01-21T13:41:05.411+0000] {base.py:73} INFO - Using connection ID 'postgres_conn' for task execution.
[2024-01-21T13:41:11.208+0000] {taskinstance.py:1937} ERROR - Task failed with exception
Traceback (most recent call last):
  File "/home/airflow/.local/lib/python3.8/site-packages/airflow/decorators/base.py", line 221, in execute
    return_value = super().execute(context)
  File "/home/airflow/.local/lib/python3.8/site-packages/airflow/operators/python.py", line 192, in execute
    return_value = self.execute_callable()
  File "/home/airflow/.local/lib/python3.8/site-packages/airflow/operators/python.py", line 209, in execute_callable
    return self.python_callable(*self.op_args, **self.op_kwargs)
  File "/opt/airflow/dags/fetch-api-data.py", line 65, in load_data
    engine.execute(query)
  File "<string>", line 2, in execute
  File "/home/airflow/.local/lib/python3.8/site-packages/sqlalchemy/util/deprecations.py", line 468, in warned
    return fn(*args, **kwargs)
  File "/home/airflow/.local/lib/python3.8/site-packages/sqlalchemy/engine/base.py", line 3267, in execute
    return connection.execute(statement, *multiparams, **params)
  File "/home/airflow/.local/lib/python3.8/site-packages/sqlalchemy/engine/base.py", line 1370, in execute
    return self._exec_driver_sql(
  File "/home/airflow/.local/lib/python3.8/site-packages/sqlalchemy/engine/base.py", line 1674, in _exec_driver_sql
    ret = self._execute_context(
  File "/home/airflow/.local/lib/python3.8/site-packages/sqlalchemy/engine/base.py", line 1953, in _execute_context
    self._handle_dbapi_exception(
  File "/home/airflow/.local/lib/python3.8/site-packages/sqlalchemy/engine/base.py", line 2138, in _handle_dbapi_exception
    util.raise_(exc_info[1], with_traceback=exc_info[2])
  File "/home/airflow/.local/lib/python3.8/site-packages/sqlalchemy/util/compat.py", line 211, in raise_
    raise exception
  File "/home/airflow/.local/lib/python3.8/site-packages/sqlalchemy/engine/base.py", line 1910, in _execute_context
    self.dialect.do_execute(
  File "/home/airflow/.local/lib/python3.8/site-packages/sqlalchemy/engine/default.py", line 736, in do_execute
    cursor.execute(statement, parameters)
TypeError: dict is not a sequence
[2024-01-21T13:41:11.230+0000] {taskinstance.py:1400} INFO - Marking task as FAILED. dag_id=data_ingestion, task_id=load_data, execution_date=20240121T134101, start_date=20240121T134105, end_date=20240121T134111
[2024-01-21T13:41:11.239+0000] {standard_task_runner.py:104} ERROR - Failed to execute job 308 for task load_data (dict is not a sequence; 39208)
[2024-01-21T13:41:11.272+0000] {local_task_job_runner.py:228} INFO - Task exited with return code 1
[2024-01-21T13:41:11.287+0000] {taskinstance.py:2778} INFO - 0 downstream tasks scheduled from follow-on schedule check
