[2024-02-22T15:02:38.058+0000] {taskinstance.py:1159} INFO - Dependencies all met for dep_context=non-requeueable deps ti=<TaskInstance: data_ingestion.load_data manual__2024-02-22T15:02:33.619252+00:00 [queued]>
[2024-02-22T15:02:38.062+0000] {taskinstance.py:1159} INFO - Dependencies all met for dep_context=requeueable deps ti=<TaskInstance: data_ingestion.load_data manual__2024-02-22T15:02:33.619252+00:00 [queued]>
[2024-02-22T15:02:38.062+0000] {taskinstance.py:1361} INFO - Starting attempt 1 of 1
[2024-02-22T15:02:38.067+0000] {taskinstance.py:1382} INFO - Executing <Task(_PythonDecoratedOperator): load_data> on 2024-02-22 15:02:33.619252+00:00
[2024-02-22T15:02:38.073+0000] {standard_task_runner.py:57} INFO - Started process 8538 to run task
[2024-02-22T15:02:38.075+0000] {standard_task_runner.py:84} INFO - Running: ['***', 'tasks', 'run', 'data_ingestion', 'load_data', 'manual__2024-02-22T15:02:33.619252+00:00', '--job-id', '391', '--raw', '--subdir', 'DAGS_FOLDER/fetch-api-data.py', '--cfg-path', '/tmp/tmptyglu1_n']
[2024-02-22T15:02:38.077+0000] {standard_task_runner.py:85} INFO - Job 391: Subtask load_data
[2024-02-22T15:02:38.108+0000] {task_command.py:416} INFO - Running <TaskInstance: data_ingestion.load_data manual__2024-02-22T15:02:33.619252+00:00 [running]> on host 8ffe65393bc1
[2024-02-22T15:02:38.210+0000] {taskinstance.py:1662} INFO - Exporting env vars: AIRFLOW_CTX_DAG_OWNER='***' AIRFLOW_CTX_DAG_ID='data_ingestion' AIRFLOW_CTX_TASK_ID='load_data' AIRFLOW_CTX_EXECUTION_DATE='2024-02-22T15:02:33.619252+00:00' AIRFLOW_CTX_TRY_NUMBER='1' AIRFLOW_CTX_DAG_RUN_ID='manual__2024-02-22T15:02:33.619252+00:00'
[2024-02-22T15:02:38.214+0000] {base.py:73} INFO - Using connection ID '***_conn' for task execution.
[2024-02-22T15:02:38.215+0000] {logging_mixin.py:154} INFO - Error while connecting to PostgreSQL 'str' object has no attribute 'connect'
[2024-02-22T15:02:38.215+0000] {taskinstance.py:1937} ERROR - Task failed with exception
Traceback (most recent call last):
  File "/home/airflow/.local/lib/python3.8/site-packages/airflow/decorators/base.py", line 221, in execute
    return_value = super().execute(context)
  File "/home/airflow/.local/lib/python3.8/site-packages/airflow/operators/python.py", line 192, in execute
    return_value = self.execute_callable()
  File "/home/airflow/.local/lib/python3.8/site-packages/airflow/operators/python.py", line 209, in execute_callable
    return self.python_callable(*self.op_args, **self.op_kwargs)
  File "/opt/airflow/dags/fetch-api-data.py", line 88, in load_data
    cursor.close()
AttributeError: 'NoneType' object has no attribute 'close'
[2024-02-22T15:02:38.219+0000] {taskinstance.py:1400} INFO - Marking task as FAILED. dag_id=data_ingestion, task_id=load_data, execution_date=20240222T150233, start_date=20240222T150238, end_date=20240222T150238
[2024-02-22T15:02:38.223+0000] {standard_task_runner.py:104} ERROR - Failed to execute job 391 for task load_data ('NoneType' object has no attribute 'close'; 8538)
[2024-02-22T15:02:38.251+0000] {local_task_job_runner.py:228} INFO - Task exited with return code 1
[2024-02-22T15:02:38.260+0000] {taskinstance.py:2778} INFO - 0 downstream tasks scheduled from follow-on schedule check
