[2024-01-14T09:00:01.533+0000] {taskinstance.py:1159} INFO - Dependencies all met for dep_context=non-requeueable deps ti=<TaskInstance: data_ingestion.fetch_data_from_api scheduled__2024-01-13T09:00:00+00:00 [queued]>
[2024-01-14T09:00:01.537+0000] {taskinstance.py:1159} INFO - Dependencies all met for dep_context=requeueable deps ti=<TaskInstance: data_ingestion.fetch_data_from_api scheduled__2024-01-13T09:00:00+00:00 [queued]>
[2024-01-14T09:00:01.537+0000] {taskinstance.py:1361} INFO - Starting attempt 1 of 1
[2024-01-14T09:00:01.544+0000] {taskinstance.py:1382} INFO - Executing <Task(_PythonDecoratedOperator): fetch_data_from_api> on 2024-01-13 09:00:00+00:00
[2024-01-14T09:00:01.549+0000] {standard_task_runner.py:57} INFO - Started process 27848 to run task
[2024-01-14T09:00:01.552+0000] {standard_task_runner.py:84} INFO - Running: ['***', 'tasks', 'run', 'data_ingestion', 'fetch_data_from_api', 'scheduled__2024-01-13T09:00:00+00:00', '--job-id', '224', '--raw', '--subdir', 'DAGS_FOLDER/fetch-api-data.py', '--cfg-path', '/tmp/tmpku3v5fjz']
[2024-01-14T09:00:01.554+0000] {standard_task_runner.py:85} INFO - Job 224: Subtask fetch_data_from_api
[2024-01-14T09:00:01.595+0000] {task_command.py:416} INFO - Running <TaskInstance: data_ingestion.fetch_data_from_api scheduled__2024-01-13T09:00:00+00:00 [running]> on host f28e5db0fcbc
[2024-01-14T09:00:01.648+0000] {taskinstance.py:1662} INFO - Exporting env vars: AIRFLOW_CTX_DAG_OWNER='***' AIRFLOW_CTX_DAG_ID='data_ingestion' AIRFLOW_CTX_TASK_ID='fetch_data_from_api' AIRFLOW_CTX_EXECUTION_DATE='2024-01-13T09:00:00+00:00' AIRFLOW_CTX_TRY_NUMBER='1' AIRFLOW_CTX_DAG_RUN_ID='scheduled__2024-01-13T09:00:00+00:00'
[2024-01-14T09:00:01.671+0000] {logging_mixin.py:154} INFO - An error occurred while fetching data: HTTPSConnectionPool(host='date.nager.at', port=443): Max retries exceeded with url: /api/v3/publicholidays/2023/NG (Caused by NewConnectionError('<urllib3.connection.HTTPSConnection object at 0xffff6e2c89d0>: Failed to establish a new connection: [Errno -2] Name or service not known'))
[2024-01-14T09:00:01.671+0000] {python.py:194} INFO - Done. Returned value was: None
[2024-01-14T09:00:01.685+0000] {taskinstance.py:1400} INFO - Marking task as SUCCESS. dag_id=data_ingestion, task_id=fetch_data_from_api, execution_date=20240113T090000, start_date=20240114T090001, end_date=20240114T090001
[2024-01-14T09:00:01.727+0000] {local_task_job_runner.py:228} INFO - Task exited with return code 0
[2024-01-14T09:00:01.740+0000] {taskinstance.py:2778} INFO - 1 downstream tasks scheduled from follow-on schedule check
