[2024-01-21T13:31:07.566+0000] {taskinstance.py:1159} INFO - Dependencies all met for dep_context=non-requeueable deps ti=<TaskInstance: data_ingestion.load_data manual__2024-01-21T13:31:02.949266+00:00 [queued]>
[2024-01-21T13:31:07.570+0000] {taskinstance.py:1159} INFO - Dependencies all met for dep_context=requeueable deps ti=<TaskInstance: data_ingestion.load_data manual__2024-01-21T13:31:02.949266+00:00 [queued]>
[2024-01-21T13:31:07.570+0000] {taskinstance.py:1361} INFO - Starting attempt 1 of 1
[2024-01-21T13:31:07.575+0000] {taskinstance.py:1382} INFO - Executing <Task(_PythonDecoratedOperator): load_data> on 2024-01-21 13:31:02.949266+00:00
[2024-01-21T13:31:07.579+0000] {standard_task_runner.py:57} INFO - Started process 38912 to run task
[2024-01-21T13:31:07.582+0000] {standard_task_runner.py:84} INFO - Running: ['***', 'tasks', 'run', 'data_ingestion', 'load_data', 'manual__2024-01-21T13:31:02.949266+00:00', '--job-id', '305', '--raw', '--subdir', 'DAGS_FOLDER/fetch-api-data.py', '--cfg-path', '/tmp/tmp077ftuww']
[2024-01-21T13:31:07.586+0000] {standard_task_runner.py:85} INFO - Job 305: Subtask load_data
[2024-01-21T13:31:07.612+0000] {task_command.py:416} INFO - Running <TaskInstance: data_ingestion.load_data manual__2024-01-21T13:31:02.949266+00:00 [running]> on host 1cee5fdf7640
[2024-01-21T13:31:07.703+0000] {taskinstance.py:1662} INFO - Exporting env vars: AIRFLOW_CTX_DAG_OWNER='***' AIRFLOW_CTX_DAG_ID='data_ingestion' AIRFLOW_CTX_TASK_ID='load_data' AIRFLOW_CTX_EXECUTION_DATE='2024-01-21T13:31:02.949266+00:00' AIRFLOW_CTX_TRY_NUMBER='1' AIRFLOW_CTX_DAG_RUN_ID='manual__2024-01-21T13:31:02.949266+00:00'
[2024-01-21T13:31:07.708+0000] {base.py:73} INFO - Using connection ID 'postgres_conn' for task execution.
[2024-01-21T13:31:07.709+0000] {taskinstance.py:1937} ERROR - Task failed with exception
Traceback (most recent call last):
  File "/home/airflow/.local/lib/python3.8/site-packages/airflow/decorators/base.py", line 221, in execute
    return_value = super().execute(context)
  File "/home/airflow/.local/lib/python3.8/site-packages/airflow/operators/python.py", line 192, in execute
    return_value = self.execute_callable()
  File "/home/airflow/.local/lib/python3.8/site-packages/airflow/operators/python.py", line 209, in execute_callable
    return self.python_callable(*self.op_args, **self.op_kwargs)
  File "/opt/airflow/dags/fetch-api-data.py", line 63, in load_data
    engine.execute(query)
AttributeError: 'str' object has no attribute 'execute'
[2024-01-21T13:31:07.713+0000] {taskinstance.py:1400} INFO - Marking task as FAILED. dag_id=data_ingestion, task_id=load_data, execution_date=20240121T133102, start_date=20240121T133107, end_date=20240121T133107
[2024-01-21T13:31:07.718+0000] {standard_task_runner.py:104} ERROR - Failed to execute job 305 for task load_data ('str' object has no attribute 'execute'; 38912)
[2024-01-21T13:31:07.755+0000] {local_task_job_runner.py:228} INFO - Task exited with return code 1
[2024-01-21T13:31:07.765+0000] {taskinstance.py:2778} INFO - 0 downstream tasks scheduled from follow-on schedule check
